[2022-03-16 00:09:56,791] {taskinstance.py:1037} INFO - Dependencies all met for <TaskInstance: 1_init_once_seed_data.load_seed_data_once manual__2022-03-16T00:09:55.582664+00:00 [queued]>
[2022-03-16 00:09:56,808] {taskinstance.py:1037} INFO - Dependencies all met for <TaskInstance: 1_init_once_seed_data.load_seed_data_once manual__2022-03-16T00:09:55.582664+00:00 [queued]>
[2022-03-16 00:09:56,809] {taskinstance.py:1243} INFO - 
--------------------------------------------------------------------------------
[2022-03-16 00:09:56,810] {taskinstance.py:1244} INFO - Starting attempt 1 of 1
[2022-03-16 00:09:56,811] {taskinstance.py:1245} INFO - 
--------------------------------------------------------------------------------
[2022-03-16 00:09:56,825] {taskinstance.py:1264} INFO - Executing <Task(BashOperator): load_seed_data_once> on 2022-03-16 00:09:55.582664+00:00
[2022-03-16 00:09:56,830] {standard_task_runner.py:52} INFO - Started process 227 to run task
[2022-03-16 00:09:56,835] {standard_task_runner.py:76} INFO - Running: ['***', 'tasks', 'run', '1_init_once_seed_data', 'load_seed_data_once', 'manual__2022-03-16T00:09:55.582664+00:00', '--job-id', '7', '--raw', '--subdir', 'DAGS_FOLDER/init.py', '--cfg-path', '/tmp/tmpz3p7deyr', '--error-file', '/tmp/tmpcpik3i8m']
[2022-03-16 00:09:56,837] {standard_task_runner.py:77} INFO - Job 7: Subtask load_seed_data_once
[2022-03-16 00:09:56,904] {logging_mixin.py:109} INFO - Running <TaskInstance: 1_init_once_seed_data.load_seed_data_once manual__2022-03-16T00:09:55.582664+00:00 [running]> on host 110616af387e
[2022-03-16 00:09:57,029] {taskinstance.py:1431} INFO - Exporting the following env vars:
AIRFLOW_CTX_DAG_OWNER=***
AIRFLOW_CTX_DAG_ID=1_init_once_seed_data
AIRFLOW_CTX_TASK_ID=load_seed_data_once
AIRFLOW_CTX_EXECUTION_DATE=2022-03-16T00:09:55.582664+00:00
AIRFLOW_CTX_DAG_RUN_ID=manual__2022-03-16T00:09:55.582664+00:00
[2022-03-16 00:09:57,031] {subprocess.py:62} INFO - Tmp dir root location: 
 /tmp
[2022-03-16 00:09:57,034] {subprocess.py:74} INFO - Running command: ['bash', '-c', 'cd /dbt && dbt seed --profiles-dir .']
[2022-03-16 00:09:57,055] {subprocess.py:85} INFO - Output:
[2022-03-16 00:10:01,091] {subprocess.py:89} INFO - Running with dbt=0.20.0
[2022-03-16 00:10:05,176] {subprocess.py:89} INFO - Encountered an error:
[2022-03-16 00:10:05,177] {subprocess.py:89} INFO - Compilation Error
[2022-03-16 00:10:05,178] {subprocess.py:89} INFO -   dbt found 2 package(s) specified in packages.yml, but only 1 package(s) installed in dbt_modules. Run "dbt deps" to install package dependencies.
[2022-03-16 00:10:05,505] {subprocess.py:93} INFO - Command exited with return code 2
[2022-03-16 00:10:05,522] {taskinstance.py:1718} ERROR - Task failed with exception
Traceback (most recent call last):
  File "/home/airflow/.local/lib/python3.7/site-packages/airflow/models/taskinstance.py", line 1334, in _run_raw_task
    self._execute_task_with_callbacks(context)
  File "/home/airflow/.local/lib/python3.7/site-packages/airflow/models/taskinstance.py", line 1460, in _execute_task_with_callbacks
    result = self._execute_task(context, self.task)
  File "/home/airflow/.local/lib/python3.7/site-packages/airflow/models/taskinstance.py", line 1516, in _execute_task
    result = execute_callable(context=context)
  File "/home/airflow/.local/lib/python3.7/site-packages/airflow/operators/bash.py", line 188, in execute
    f'Bash command failed. The command returned a non-zero exit code {result.exit_code}.'
airflow.exceptions.AirflowException: Bash command failed. The command returned a non-zero exit code 2.
[2022-03-16 00:10:05,533] {taskinstance.py:1282} INFO - Marking task as FAILED. dag_id=1_init_once_seed_data, task_id=load_seed_data_once, execution_date=20220316T000955, start_date=20220316T000956, end_date=20220316T001005
[2022-03-16 00:10:05,550] {standard_task_runner.py:92} ERROR - Failed to execute job 7 for task load_seed_data_once
Traceback (most recent call last):
  File "/home/airflow/.local/lib/python3.7/site-packages/airflow/task/task_runner/standard_task_runner.py", line 85, in _start_by_fork
    args.func(args, dag=self.dag)
  File "/home/airflow/.local/lib/python3.7/site-packages/airflow/cli/cli_parser.py", line 48, in command
    return func(*args, **kwargs)
  File "/home/airflow/.local/lib/python3.7/site-packages/airflow/utils/cli.py", line 92, in wrapper
    return f(*args, **kwargs)
  File "/home/airflow/.local/lib/python3.7/site-packages/airflow/cli/commands/task_command.py", line 298, in task_run
    _run_task_by_selected_method(args, dag, ti)
  File "/home/airflow/.local/lib/python3.7/site-packages/airflow/cli/commands/task_command.py", line 107, in _run_task_by_selected_method
    _run_raw_task(args, ti)
  File "/home/airflow/.local/lib/python3.7/site-packages/airflow/cli/commands/task_command.py", line 184, in _run_raw_task
    error_file=args.error_file,
  File "/home/airflow/.local/lib/python3.7/site-packages/airflow/utils/session.py", line 70, in wrapper
    return func(*args, session=session, **kwargs)
  File "/home/airflow/.local/lib/python3.7/site-packages/airflow/models/taskinstance.py", line 1334, in _run_raw_task
    self._execute_task_with_callbacks(context)
  File "/home/airflow/.local/lib/python3.7/site-packages/airflow/models/taskinstance.py", line 1460, in _execute_task_with_callbacks
    result = self._execute_task(context, self.task)
  File "/home/airflow/.local/lib/python3.7/site-packages/airflow/models/taskinstance.py", line 1516, in _execute_task
    result = execute_callable(context=context)
  File "/home/airflow/.local/lib/python3.7/site-packages/airflow/operators/bash.py", line 188, in execute
    f'Bash command failed. The command returned a non-zero exit code {result.exit_code}.'
airflow.exceptions.AirflowException: Bash command failed. The command returned a non-zero exit code 2.
[2022-03-16 00:10:05,575] {local_task_job.py:154} INFO - Task exited with return code 1
[2022-03-16 00:10:05,611] {local_task_job.py:264} INFO - 0 downstream tasks scheduled from follow-on schedule check
